Workbook

Sheet 📋 Instructions
B1: RACI RESPONSIBILITY ASSIGNMENT MATRIX | Project Governance Tool
B5: Version 1.0 | Last Updated: [Date] | Project: [Project Name] | Status: [ACTIVE]
B7: 🎯 PURPOSE OF THIS TEMPLATE
B8: Why RACI? | C8: Unclear roles cause 40-60% of project delays. This template defines WHO does WHAT, WHO decides, WHO advises, and WHO needs updates — eliminating ambiguity before it derails your project.
B9: When to build it? | C9: During project INITIATION — before sprint planning, resource allocation, or vendor kick-off. Review at every phase gate and whenever team members change.
B10: Golden Rule | C10: Every task must have ✅ exactly ONE Accountable (A). Multiple A's = nobody is accountable. Zero A's = no owner. The Health Check tab flags both automatically.
B12: 📌 RACI DEFINITIONS & USAGE RULES
B13: R | C13: RESPONSIBLE — The person or team who performs the actual work. There can be multiple R's.
C14: ▸ Rule: At least ONE R per task. Tag individuals, not just departments.
B17: A | C17: ACCOUNTABLE — The single owner who approves the outcome and answers for it. The 'buck stops here' role.
C18: ▸ Rule: ⚠️ EXACTLY ONE per task — never zero, never two. Usually a senior role.
B21: C | C21: CONSULTED — Subject matter experts who provide input BEFORE a decision is made. Two-way dialogue.
C22: ▸ Rule: Use sparingly. Too many C's slow decisions. Limit to true SMEs with relevant expertise.
B25: I | C25: INFORMED — Stakeholders who receive updates AFTER decisions/milestones. One-way communication.
C26: ▸ Rule: Prefer I over C when input is not needed. Over-consulting inflates meeting load.
B29: 🗂️ WORKBOOK STRUCTURE — 5 SHEETS
B30: 📋 Instructions | C30: This sheet. Read before use.
B31: 🎯 RACI Matrix | C31: MAIN WORKING SHEET. Enter R / A / C / I for each task × stakeholder cell. Use the dropdown.
B32: 👥 Stakeholders | C32: Register all project stakeholders: name, role, department, email. Feed names into the matrix.
B33: 📊 Health Check | C33: Auto-calculated dashboard. Flags missing A, duplicate A, over-consulted roles, orphan tasks.
B34: 📝 Change Log | C34: Record every RACI change: who changed what, when, and why. Audit trail for governance.
B36: 🚨 COMMON RACI FAILURES & HOW THIS TEMPLATE PREVENTS THEM
B37: FAILURE | C37: HOW THIS TEMPLATE ADDRESSES IT
B38: ⚠ Multiple owners = no owner | C38: ✅ Health Check flags any task with more than one A in red. One A only, enforced visually.
B39: ⚠ 'IT will handle it' ambiguity | C39: ✅ Stakeholder sheet maps individuals — no department-level assignments allowed.
B40: ⚠ Vendor accountability gaps | C40: ✅ Vendor rows included in stakeholder register. Vendor PM must hold A or R on delivery tasks.
B41: ⚠ Sponsor not looped in | C41: ✅ Sponsor column pre-built. Health Check warns if Sponsor has zero I assignments.
B42: ⚠ RACI not updated after change | C42: ✅ Change Log tab records every update. Version + date tracked in cell B5 of each sheet.
B43: ⚠ QA/UAT ownership confusion | C43: ✅ Dedicated phase rows for QA sign-off, UAT approval with explicit A separation.
B44: ⚠ Data migration nobody owns | C44: ✅ Data Migration phase pre-populated — the #1 real-world failure scenario.
B45: ⚠ Too many Consulted = slow | C45: ✅ Health Check shows Consulted count per role. Flags roles over-burdened with C's.
B47: 💡 Tip: Use Ctrl+F to search tasks. Freeze panes are set on all working sheets. Filter by phase using the dropdown in column A of the RACI Matrix.

Sheet 👥 Stakeholders
A1: 👥 STAKEHOLDER REGISTER — Add all project stakeholders here. Names auto-populate RACI column headers.
A2: ID | B2: Full Name | C2: Role / Title | D2: Department | E2: Organisation | F2: Email | G2: Type | H2: RACI Code (Default) | I2: Notes / Delegation
A3: S01 | B3: [Sponsor Name] | C3: Executive Sponsor | D3: Executive | E3: Internal | F3: sponsor@company.com | G3: Internal | H3: A | I3: Final approver for scope, budget, go/no-go
A4: S02 | B4: [PM Name] | C4: Project Manager | D4: PMO | E4: Internal | F4: pm@company.com | G4: Internal | H4: A | I4: Day-to-day RACI owner. Update this register on any change.
A5: S03 | B5: [Tech Lead] | C5: Technical Lead / Architect | D5: Technology | E5: Internal | F5: tech@company.com | G5: Internal | H5: R | I5: Responsible for architecture decisions and IT delivery
A6: S04 | B6: [Business Analyst] | C6: Business Analyst | D6: Business | E6: Internal | F6: ba@company.com | G6: Internal | H6: R | I6: Requirements, process mapping, UAT coordination
A7: S05 | B7: [QA Lead] | C7: QA / Test Manager | D7: Quality | E7: Internal | F7: qa@company.com | G7: Internal | H7: R | I7: Test strategy, defect management, sign-off
A8: S06 | B8: [Finance Lead] | C8: Finance Manager | D8: Finance | E8: Internal | F8: finance@company.com | G8: Internal | H8: A | I8: Accountable for data accuracy in migration & budget
A9: S07 | B9: [Change Manager] | C9: Change & Comms Lead | D9: HR / Change | E9: Internal | F9: change@company.com | G9: Internal | H9: R | I9: Training, comms plan, adoption metrics
A10: S08 | B10: [InfoSec] | C10: Information Security Officer | D10: IT Security | E10: Internal | F10: infosec@company.com | G10: Internal | H10: C | I10: Consulted on security, DPIA, access controls
A11: S09 | B11: [Vendor PM] | C11: Vendor Project Manager | D11: Vendor | E11: External | F11: vendor.pm@vendor.com | G11: Vendor | H11: R | I11: Accountable for vendor deliverables and SLAs
A12: S10 | B12: [Vendor Tech] | C12: Vendor Technical Lead | D12: Vendor | E12: External | F12: vendor.tech@vendor.com | G12: Vendor | H12: R | I12: Responsible for vendor configuration/build
A13: S11 | B13: [Legal / DPA] | C13: Legal / Data Protection | D13: Legal | E13: Internal | F13: legal@company.com | G13: Internal | H13: C | I13: Consulted on GDPR/DPA, contracts, compliance
... A16: S14 | B16: [3rd Party Audit] | C16: External Auditor | D16: Audit | E16: External | F16: audit@auditor.com | G16: External | H16: I | I16: Informed on compliance and controls

Sheet 🎯 RACI Matrix
A1: 🎯 RACI RESPONSIBILITY ASSIGNMENT MATRIX
A4: Project: [Name] | Phase: [Current Phase] | Version: 1.0 | Date: [Date] | RAG Status: [🟡 AMBER]
A5: LEGEND: | D5: R | E5: Responsible | F5: A | G5: Accountable | H5: C | I5: Consulted | J5: I | K5: Informed | L5: ⚠ ONE 'A' per row only | Every task needs at least one 'R'
A6: Phase | B6: # | C6: Task / Deliverable | D6: Priority | E6: Description / Acceptance Criteria | F6: Sponsor | G6: Project Manager | H6: Tech Lead | I6: Business Analyst | J6: QA Lead | K6: Finance Mgr | L6: Change Mgr | M6: InfoSec | N6: Vendor PM | O6: Vendor Tech | P6: Legal/ DPA | Q6: User Rep | R6: Steering Comm | S6: Notes / Escalation Path | T6: RACI Status
A8: 🔵 Initiation
A9: 🔵 Initiation | B9: 1.1 | C9: Project Charter Sign-Off | D9: 🔴 High | E9: Formal approval of project charter, scope, budget, and objectives | F9: A | G9: R | H9: C | I9: C | K9: C | N9: I | P9: C | R9: I | S9: Sponsor A is non-negotiable. Escalate to Steering if delayed. | T9: =IF(COUNTIF(F9:R9,"A")>1,"⚠ Multi-A",IF(COUNTIF(F9:R9,"A")=0,"⚠ No A",IF(COUNTIF(F9:R9,"R")=0,"⚠ No R","✅ OK"))) -> ✅ OK
A10: 🔵 Initiation | B10: 1.2 | C10: Stakeholder Register Creation | D10: 🔴 High | E10: Identify all stakeholders, roles, and communication needs | F10: I | G10: A | H10: C | I10: R | L10: C | N10: I | P10: C | R10: I | S10: PM owns. Review with Sponsor before circulating. | T10: =IF(COUNTIF(F10:R10,"A")>1,"⚠ Multi-A",IF(COUNTIF(F10:R10,"A")=0,"⚠ No A",IF(COUNTIF(F10:R10,"R")=0,"⚠ No R","✅ OK"))) -> ✅ OK
A11: 🔵 Initiation | B11: 1.3 | C11: RACI Matrix Agreement | D11: 🔴 High | E11: Define and obtain sign-off on roles and responsibilities across all phases | F11: A | G11: R | H11: C | I11: C | J11: C | K11: C | L11: C | M11: C | N11: C | R11: I | S11: ⚠ This very document. Signed version = project authority. | T11: =IF(COUNTIF(F11:R11,"A")>1,"⚠ Multi-A",IF(COUNTIF(F11:R11,"A")=0,"⚠ No A",IF(COUNTIF(F11:R11,"R")=0,"⚠ No R","✅ OK"))) -> ✅ OK
A12: 🔵 Initiation | B12: 1.4 | C12: Project Governance Framework | D12: 🔴 High | E12: Establish steering cadence, escalation path, decision authority levels | F12: A | G12: R | H12: C | I12: C | K12: C | M12: C | N12: I | P12: C | R12: C | S12: Governance gaps cause most escalation failures. | T12: =IF(COUNTIF(F12:R12,"A")>1,"⚠ Multi-A",IF(COUNTIF(F12:R12,"A")=0,"⚠ No A",IF(COUNTIF(F12:R12,"R")=0,"⚠ No R","✅ OK"))) -> ✅ OK
A13: 🔵 Initiation | B13: 1.5 | C13: Budget Baseline & Approval | D13: 🔴 High | E13: Confirm approved budget, contingency reserve, and change request thresholds | F13: A | G13: R | H13: C | K13: R | N13: I | R13: I | S13: Finance co-owns. Document approval thresholds clearly. | T13: =IF(COUNTIF(F13:R13,"A")>1,"⚠ Multi-A",IF(COUNTIF(F13:R13,"A")=0,"⚠ No A",IF(COUNTIF(F13:R13,"R")=0,"⚠ No R","✅ OK"))) -> ✅ OK
A14: 🔵 Initiation | B14: 1.6 | C14: DPIA / InfoSec Review Initiation | D14: 🟡 Med | E14: Initiate Data Protection Impact Assessment and InfoSec onboarding | F14: I | G14: R | H14: C | I14: C | M14: A | N14: I | P14: C | R14: I | S14: InfoSec A. Start early — late DPIA = project stop. | T14: =IF(COUNTIF(F14:R14,"A")>1,"⚠ Multi-A",IF(COUNTIF(F14:R14,"A")=0,"⚠ No A",IF(COUNTIF(F14:R14,"R")=0,"⚠ No R","✅ OK"))) -> ✅ OK
A15: 🔵 Initiation | B15: 1.7 | C15: Vendor Contract / SOW Sign-Off | D15: 🔴 High | E15: Execute vendor Statement of Work, SLAs, and penalty clauses | F15: A | G15: R | H15: C | K15: C | N15: R | P15: C | R15: I | S15: Legal must review before signature. No verbal agreements. | T15: =IF(COUNTIF(F15:R15,"A")>1,"⚠ Multi-A",IF(COUNTIF(F15:R15,"A")=0,"⚠ No A",IF(COUNTIF(F15:R15,"R")=0,"⚠ No R","✅ OK"))) -> ✅ OK
A16: 🟣 Planning
A17: 🟣 Planning | B17: 2.1 | C17: Project Plan & Schedule Baseline | D17: 🔴 High | E17: Develop integrated project schedule with milestones, dependencies, and resources | F17: I | G17: A | H17: C | I17: C | J17: C | L17: C | N17: C | R17: I | S17: PM owns the baseline. Lock before sprint start. | T17: =IF(COUNTIF(F17:R17,"A")>1,"⚠ Multi-A",IF(COUNTIF(F17:R17,"A")=0,"⚠ No A",IF(COUNTIF(F17:R17,"R")=0,"⚠ No R","✅ OK"))) -> ⚠ No R
A18: 🟣 Planning | B18: 2.2 | C18: Requirements Sign-Off | D18: 🔴 High | E18: Business requirements documented, reviewed, baselined, and approved | F18: A | G18: R | H18: C | I18: R | J18: C | K18: C | L18: C | M18: C | N18: I | O18: I | P18: C | Q18: C | R18: I | S18: BA leads. Sponsor A. User Rep must validate. | T18: =IF(COUNTIF(F18:R18,"A")>1,"⚠ Multi-A",IF(COUNTIF(F18:R18,"A")=0,"⚠ No A",IF(COUNTIF(F18:R18,"R")=0,"⚠ No R","✅ OK"))) -> ✅ OK
A19: 🟣 Planning | B19: 2.3 | C19: Architecture & Solution Design | D19: 🔴 High | E19: Technical architecture approved, integration points confirmed | F19: I | G19: C | H19: A | I19: C | J19: C | M19: C | N19: R | O19: R | R19: I | S19: Tech Lead A. Vendor co-delivers. InfoSec review mandatory. | T19: =IF(COUNTIF(F19:R19,"A")>1,"⚠ Multi-A",IF(COUNTIF(F19:R19,"A")=0,"⚠ No A",IF(COUNTIF(F19:R19,"R")=0,"⚠ No R","✅ OK"))) -> ✅ OK
A20: 🟣 Planning | B20: 2.4 | C20: Test Strategy & Plan | D20: 🟡 Med | E20: Define test types, environments, entry/exit criteria, and defect SLAs | F20: I | G20: C | H20: C | I20: C | J20: A | N20: I | O20: I | Q20: C | R20: I | S20: QA owns fully. Tech Lead consulted on environments. | T20: =IF(COUNTIF(F20:R20,"A")>1,"⚠ Multi-A",IF(COUNTIF(F20:R20,"A")=0,"⚠ No A",IF(COUNTIF(F20:R20,"R")=0,"⚠ No R","✅ OK"))) -> ⚠ No R
A21: 🟣 Planning | B21: 2.5 | C21: Change Management Plan | D21: 🟡 Med | E21: Stakeholder engagement, training, comms, and resistance management plan | F21: I | G21: C | I21: C | L21: A | N21: I | Q21: C | R21: I | S21: Change Mgr A. Sponsor to review tone and messaging. | T21: =IF(COUNTIF(F21:R21,"A")>1,"⚠ Multi-A",IF(COUNTIF(F21:R21,"A")=0,"⚠ No A",IF(COUNTIF(F21:R21,"R")=0,"⚠ No R","✅ OK"))) -> ⚠ No R
A22: 🟣 Planning | B22: 2.6 | C22: Risk Register Setup | D22: 🟡 Med | E22: Identify, score, assign owners to top 10 risks. Baseline RAID register | F22: I | G22: A | H22: C | I22: C | J22: C | K22: C | L22: C | M22: C | N22: R | P22: C | R22: I | S22: PM maintains. All leads contribute. Review fortnightly. | T22: =IF(COUNTIF(F22:R22,"A")>1,"⚠ Multi-A",IF(COUNTIF(F22:R22,"A")=0,"⚠ No A",IF(COUNTIF(F22:R22,"R")=0,"⚠ No R","✅ OK"))) -> ✅ OK
A23: 🟣 Planning | B23: 2.7 | C23: Data Migration Strategy | D23: 🔴 High | E23: Define migration approach, data quality rules, rollback plan, and sign-off owner | F23: I | G23: C | H23: R | I23: C | J23: C | K23: A | M23: C | N23: R | O23: R | R23: I | S23: ⚠ Finance A for data accuracy. The #1 real-world failure point. | T23: =IF(COUNTIF(F23:R23,"A")>1,"⚠ Multi-A",IF(COUNTIF(F23:R23,"A")=0,"⚠ No A",IF(COUNTIF(F23:R23,"R")=0,"⚠ No R","✅ OK"))) -> ✅ OK
A24: 🟠 Design
A25: 🟠 Design | B25: 3.1 | C25: UX / UI Design Approval | D25: 🟡 Med | E25: Wireframes, prototypes, and design standards reviewed and approved by business | F25: I | G25: C | H25: C | I25: A | J25: C | L25: C | N25: R | O25: R | Q25: C | R25: I | S25: BA/Business owns approval. Vendor delivers. | T25: =IF(COUNTIF(F25:R25,"A")>1,"⚠ Multi-A",IF(COUNTIF(F25:R25,"A")=0,"⚠ No A",IF(COUNTIF(F25:R25,"R")=0,"⚠ No R","✅ OK"))) -> ✅ OK
A26: 🟠 Design | B26: 3.2 | C26: Integration Design Sign-Off | D26: 🔴 High | E26: API contracts, integration patterns, and data flows approved | F26: I | G26: C | H26: A | I26: C | J26: C | M26: C | N26: R | O26: R | R26: I | S26: Tech Lead A. Vendor R. No build without approved design. | T26: =IF(COUNTIF(F26:R26,"A")>1,"⚠ Multi-A",IF(COUNTIF(F26:R26,"A")=0,"⚠ No A",IF(COUNTIF(F26:R26,"R")=0,"⚠ No R","✅ OK"))) -> ✅ OK
A27: 🟠 Design | B27: 3.3 | C27: Security Design Review | D27: 🔴 High | E27: Security controls, access model, encryption, and audit logging reviewed | F27: I | G27: C | H27: R | M27: A | N27: R | O27: R | P27: C | R27: I | S27: InfoSec A. Mandatory gate before build commences. | T27: =IF(COUNTIF(F27:R27,"A")>1,"⚠ Multi-A",IF(COUNTIF(F27:R27,"A")=0,"⚠ No A",IF(COUNTIF(F27:R27,"R")=0,"⚠ No R","✅ OK"))) -> ✅ OK
A28: 🟠 Design | B28: 3.4 | C28: Data Model & Dictionary Approval | D28: 🟡 Med | E28: Logical data model, field definitions, and data dictionary reviewed | F28: I | G28: C | H28: C | I28: R | K28: C | M28: C | N28: R | O28: R | R28: I | S28: BA leads. Finance consulted for financial data fields. | T28: =IF(COUNTIF(F28:R28,"A")>1,"⚠ Multi-A",IF(COUNTIF(F28:R28,"A")=0,"⚠ No A",IF(COUNTIF(F28:R28,"R")=0,"⚠ No R","✅ OK"))) -> ⚠ No A
A29: 🔨 Build
A30: 🔨 Build | B30: 4.1 | C30: Sprint / Development Execution | D30: 🔴 High | E30: Agile sprints delivered per plan, code reviewed, and unit tested | F30: I | G30: C | H30: R | I30: C | J30: C | N30: A | O30: R | R30: I | S30: Vendor PM A for delivery. Tech Lead technical oversight. | T30: =IF(COUNTIF(F30:R30,"A")>1,"⚠ Multi-A",IF(COUNTIF(F30:R30,"A")=0,"⚠ No A",IF(COUNTIF(F30:R30,"R")=0,"⚠ No R","✅ OK"))) -> ✅ OK
A31: 🔨 Build | B31: 4.2 | C31: Infrastructure & Environment Setup | D31: 🔴 High | E31: Dev, Test, UAT, and Prod environments provisioned and validated | F31: I | G31: C | H31: A | J31: C | M31: C | N31: R | O31: R | R31: I | S31: Tech Lead A. Vendor delivers. InfoSec reviews prod config. | T31: =IF(COUNTIF(F31:R31,"A")>1,"⚠ Multi-A",IF(COUNTIF(F31:R31,"A")=0,"⚠ No A",IF(COUNTIF(F31:R31,"R")=0,"⚠ No R","✅ OK"))) -> ✅ OK
A32: 🔨 Build | B32: 4.3 | C32: Configuration & Customisation | D32: 🔴 High | E32: Platform configured per approved design. Deviations logged as change requests | F32: I | G32: C | H32: C | I32: C | J32: C | N32: A | O32: R | R32: I | S32: Vendor PM A. Every deviation triggers change control. | T32: =IF(COUNTIF(F32:R32,"A")>1,"⚠ Multi-A",IF(COUNTIF(F32:R32,"A")=0,"⚠ No A",IF(COUNTIF(F32:R32,"R")=0,"⚠ No R","✅ OK"))) -> ✅ OK
A33: 🔨 Build | B33: 4.4 | C33: Integration Build & Unit Test | D33: 🔴 High | E33: APIs built, connected, and unit tested. Results documented | F33: I | G33: C | H33: A | I33: C | J33: C | N33: R | O33: R | R33: I | S33: Tech Lead A for integration quality. | T33: =IF(COUNTIF(F33:R33,"A")>1,"⚠ Multi-A",IF(COUNTIF(F33:R33,"A")=0,"⚠ No A",IF(COUNTIF(F33:R33,"R")=0,"⚠ No R","✅ OK"))) -> ✅ OK
A34: 🔨 Build | B34: 4.5 | C34: Data Migration Build | D34: 🔴 High | E34: ETL scripts built, tested in Dev environment, data quality rules applied | F34: I | G34: C | H34: R | I34: C | J34: C | K34: A | M34: C | N34: R | O34: R | R34: I | S34: Finance A for data accuracy. Run multiple dress rehearsals. | T34: =IF(COUNTIF(F34:R34,"A")>1,"⚠ Multi-A",IF(COUNTIF(F34:R34,"A")=0,"⚠ No A",IF(COUNTIF(F34:R34,"R")=0,"⚠ No R","✅ OK"))) -> ✅ OK
A35: 🧪 Testing
A36: 🧪 Testing | B36: 5.1 | C36: System Integration Testing (SIT) | D36: 🔴 High | E36: End-to-end system test across all integrated components | F36: I | G36: C | H36: R | I36: C | J36: A | N36: R | O36: R | R36: I | S36: QA A. Vendor co-responsible. Exit criteria: zero Sev-1 defects. | T36: =IF(COUNTIF(F36:R36,"A")>1,"⚠ Multi-A",IF(COUNTIF(F36:R36,"A")=0,"⚠ No A",IF(COUNTIF(F36:R36,"R")=0,"⚠ No R","✅ OK"))) -> ✅ OK
A37: 🧪 Testing | B37: 5.2 | C37: Performance & Load Testing | D37: 🟡 Med | E37: System performance validated against agreed SLAs under peak load | F37: I | G37: C | H37: A | J37: R | N37: R | O37: R | R37: I | S37: Tech Lead A. Define pass criteria before test start. | T37: =IF(COUNTIF(F37:R37,"A")>1,"⚠ Multi-A",IF(COUNTIF(F37:R37,"A")=0,"⚠ No A",IF(COUNTIF(F37:R37,"R")=0,"⚠ No R","✅ OK"))) -> ✅ OK
A38: 🧪 Testing | B38: 5.3 | C38: Security Penetration Testing | D38: 🔴 High | E38: External pen test or InfoSec scan completed and findings remediated | F38: I | G38: C | H38: R | J38: C | M38: A | N38: R | O38: R | R38: I | S38: InfoSec A. Mandatory gate. No go-live without clear pen test. | T38: =IF(COUNTIF(F38:R38,"A")>1,"⚠ Multi-A",IF(COUNTIF(F38:R38,"A")=0,"⚠ No A",IF(COUNTIF(F38:R38,"R")=0,"⚠ No R","✅ OK"))) -> ✅ OK
A39: 🧪 Testing | B39: 5.4 | C39: Defect Management | D39: 🔴 High | E39: Defects logged, triaged, assigned, tracked to closure. SLA tracked | F39: I | G39: C | H39: R | I39: C | J39: A | N39: R | O39: R | R39: I | S39: QA owns defect register. Daily triage during SIT/UAT. | T39: =IF(COUNTIF(F39:R39,"A")>1,"⚠ Multi-A",IF(COUNTIF(F39:R39,"A")=0,"⚠ No A",IF(COUNTIF(F39:R39,"R")=0,"⚠ No R","✅ OK"))) -> ✅ OK
A40: 🧪 Testing | B40: 5.5 | C40: UAT Planning & Execution | D40: 🔴 High | E40: Business users execute UAT scenarios. Issues logged and resolved | F40: I | G40: R | H40: C | I40: R | J40: C | K40: C | L40: C | N40: I | Q40: A | R40: I | S40: User Rep A for UAT execution. BA coordinates. | T40: =IF(COUNTIF(F40:R40,"A")>1,"⚠ Multi-A",IF(COUNTIF(F40:R40,"A")=0,"⚠ No A",IF(COUNTIF(F40:R40,"R")=0,"⚠ No R","✅ OK"))) -> ✅ OK
A41: 🧪 Testing | B41: 5.6 | C41: UAT Sign-Off | D41: 🔴 High | E41: Formal business sign-off that system meets requirements and is fit for purpose | F41: A | G41: R | H41: C | I41: C | J41: C | K41: C | N41: I | Q41: C | R41: I | S41: Sponsor A. Non-negotiable gate before go-live decision. | T41: =IF(COUNTIF(F41:R41,"A")>1,"⚠ Multi-A",IF(COUNTIF(F41:R41,"A")=0,"⚠ No A",IF(COUNTIF(F41:R41,"R")=0,"⚠ No R","✅ OK"))) -> ✅ OK
A42: 📦 Data Migr.
A43: 📦 Data Migr. | B43: 6.1 | C43: Data Cleanse & Extraction | D43: 🔴 High | E43: Source data extracted, validated, and cleansed per migration rules | F43: I | G43: C | H43: R | I43: C | J43: C | K43: A | M43: C | N43: R | O43: R | R43: I | S43: Finance A. ⚠ The classic failure: 'IT thought business would do this' | T43: =IF(COUNTIF(F43:R43,"A")>1,"⚠ Multi-A",IF(COUNTIF(F43:R43,"A")=0,"⚠ No A",IF(COUNTIF(F43:R43,"R")=0,"⚠ No R","✅ OK"))) -> ✅ OK
...

Sheet 📊 Health Check
B1: 📊 RACI HEALTH CHECK DASHBOARD — Auto-calculated. Review before each phase gate.
B5: 🔴 CRITICAL CHECKS — Must be zero before phase gate
B6: Tasks with MULTIPLE Accountables (A) | C6: =COUNTIF('🎯 RACI Matrix'!T8:T59,"⚠ Multi-A") -> 0 | D6: =IF(C6=0,"✅ GOOD","🚨 FIX NOW") -> ✅ GOOD | E6: Every task must have EXACTLY one A. Multiple A = no real owner.
B7: Tasks with NO Accountable (A) | C7: =COUNTIF('🎯 RACI Matrix'!T8:T59,"⚠ No A") -> 1 | D7: =IF(C7=0,"✅ GOOD","🚨 FIX NOW") -> 🚨 FIX NOW | E7: Unowned tasks slip. Someone must be accountable for every deliverable.
B8: Tasks with NO Responsible (R) | C8: =COUNTIF('🎯 RACI Matrix'!T8:T59,"⚠ No R") -> 5 | D8: =IF(C8=0,"✅ GOOD","🚨 FIX NOW") -> 🚨 FIX NOW | E8: No R = nobody is doing the work. Always name the doer.
B10: 📊 SUMMARY METRICS — Overall RACI completeness
B11: Total Tasks in Matrix | C11: =59-8+1 -> 52
B12: Tasks with valid RACI (✅ OK) | C12: =COUNTIF('🎯 RACI Matrix'!T8:T59,"✅ OK") -> 38
B13: RACI Completeness % | C13: =IFERROR(C12/52,0) -> 0.73076923
B15: 👥 ROLE WORKLOAD ANALYSIS — Responsibility distribution per stakeholder
B16: Stakeholder | C16: # Responsible (R) | D16: # Accountable (A) | E16: # Consulted (C) | F16: # Informed (I) | G16: Total Assignments | H16: Workload Flag
B17: Sponsor | C17: =COUNTIF('🎯 RACI Matrix'!F8:F59,"R") -> 0 | D17: =COUNTIF('🎯 RACI Matrix'!F8:F59,"A") -> 12 | E17: =COUNTIF('🎯 RACI Matrix'!F8:F59,"C") -> 0 | F17: =COUNTIF('🎯 RACI Matrix'!F8:F59,"I") -> 32 | G17: =C17+D17+E17+F17 -> 44 | H17: =IF(E17>8,"⚠ Over-consulted",IF(C17+D17=0,"⚠ No R/A","✅ OK")) -> ✅ OK
B18: Project Manager | C18: =COUNTIF('🎯 RACI Matrix'!G8:G59,"R") -> 15 | D18: =COUNTIF('🎯 RACI Matrix'!G8:G59,"A") -> 7 | E18: =COUNTIF('🎯 RACI Matrix'!G8:G59,"C") -> 22 | F18: =COUNTIF('🎯 RACI Matrix'!G8:G59,"I") -> 0 | G18: =C18+D18+E18+F18 -> 44 | H18: =IF(E18>8,"⚠ Over-consulted",IF(C18+D18=0,"⚠ No R/A","✅ OK")) -> ⚠ Over-consulted
B19: Tech Lead | C19: =COUNTIF('🎯 RACI Matrix'!H8:H59,"R") -> 15 | D19: =COUNTIF('🎯 RACI Matrix'!H8:H59,"A") -> 5 | E19: =COUNTIF('🎯 RACI Matrix'!H8:H59,"C") -> 20 | F19: =COUNTIF('🎯 RACI Matrix'!H8:H59,"I") -> 0 | G19: =C19+D19+E19+F19 -> 40 | H19: =IF(E19>8,"⚠ Over-consulted",IF(C19+D19=0,"⚠ No R/A","✅ OK")) -> ⚠ Over-consulted
B20: Business Analyst | C20: =COUNTIF('🎯 RACI Matrix'!I8:I59,"R") -> 5 | D20: =COUNTIF('🎯 RACI Matrix'!I8:I59,"A") -> 1 | E20: =COUNTIF('🎯 RACI Matrix'!I8:I59,"C") -> 30 | F20: =COUNTIF('🎯 RACI Matrix'!I8:I59,"I") -> 0 | G20: =C20+D20+E20+F20 -> 36 | H20: =IF(E20>8,"⚠ Over-consulted",IF(C20+D20=0,"⚠ No R/A","✅ OK")) -> ⚠ Over-consulted
B21: QA Lead | C21: =COUNTIF('🎯 RACI Matrix'!J8:J59,"R") -> 6 | D21: =COUNTIF('🎯 RACI Matrix'!J8:J59,"A") -> 3 | E21: =COUNTIF('🎯 RACI Matrix'!J8:J59,"C") -> 22 | F21: =COUNTIF('🎯 RACI Matrix'!J8:J59,"I") -> 0 | G21: =C21+D21+E21+F21 -> 31 | H21: =IF(E21>8,"⚠ Over-consulted",IF(C21+D21=0,"⚠ No R/A","✅ OK")) -> ⚠ Over-consulted
B22: Finance Mgr | C22: =COUNTIF('🎯 RACI Matrix'!K8:K59,"R") -> 1 | D22: =COUNTIF('🎯 RACI Matrix'!K8:K59,"A") -> 6 | E22: =COUNTIF('🎯 RACI Matrix'!K8:K59,"C") -> 16 | F22: =COUNTIF('🎯 RACI Matrix'!K8:K59,"I") -> 0 | G22: =C22+D22+E22+F22 -> 23 | H22: =IF(E22>8,"⚠ Over-consulted",IF(C22+D22=0,"⚠ No R/A","✅ OK")) -> ⚠ Over-consulted
B23: Change Mgr | C23: =COUNTIF('🎯 RACI Matrix'!L8:L59,"R") -> 2 | D23: =COUNTIF('🎯 RACI Matrix'!L8:L59,"A") -> 3 | E23: =COUNTIF('🎯 RACI Matrix'!L8:L59,"C") -> 12 | F23: =COUNTIF('🎯 RACI Matrix'!L8:L59,"I") -> 0 | G23: =C23+D23+E23+F23 -> 17 | H23: =IF(E23>8,"⚠ Over-consulted",IF(C23+D23=0,"⚠ No R/A","✅ OK")) -> ⚠ Over-consulted
B24: InfoSec | C24: =COUNTIF('🎯 RACI Matrix'!M8:M59,"R") -> 0 | D24: =COUNTIF('🎯 RACI Matrix'!M8:M59,"A") -> 3 | E24: =COUNTIF('🎯 RACI Matrix'!M8:M59,"C") -> 15 | F24: =COUNTIF('🎯 RACI Matrix'!M8:M59,"I") -> 0 | G24: =C24+D24+E24+F24 -> 18 | H24: =IF(E24>8,"⚠ Over-consulted",IF(C24+D24=0,"⚠ No R/A","✅ OK")) -> ⚠ Over-consulted
B25: Vendor PM | C25: =COUNTIF('🎯 RACI Matrix'!N8:N59,"R") -> 24 | D25: =COUNTIF('🎯 RACI Matrix'!N8:N59,"A") -> 2 | E25: =COUNTIF('🎯 RACI Matrix'!N8:N59,"C") -> 3 | F25: =COUNTIF('🎯 RACI Matrix'!N8:N59,"I") -> 15 | G25: =C25+D25+E25+F25 -> 44 | H25: =IF(E25>8,"⚠ Over-consulted",IF(C25+D25=0,"⚠ No R/A","✅ OK")) -> ✅ OK
B26: Vendor Tech | C26: =COUNTIF('🎯 RACI Matrix'!O8:O59,"R") -> 22 | D26: =COUNTIF('🎯 RACI Matrix'!O8:O59,"A") -> 0 | E26: =COUNTIF('🎯 RACI Matrix'!O8:O59,"C") -> 0 | F26: =COUNTIF('🎯 RACI Matrix'!O8:O59,"I") -> 2 | G26: =C26+D26+E26+F26 -> 24 | H26: =IF(E26>8,"⚠ Over-consulted",IF(C26+D26=0,"⚠ No R/A","✅ OK")) -> ✅ OK
B27: Legal/ DPA | C27: =COUNTIF('🎯 RACI Matrix'!P8:P59,"R") -> 0 | D27: =COUNTIF('🎯 RACI Matrix'!P8:P59,"A") -> 0 | E27: =COUNTIF('🎯 RACI Matrix'!P8:P59,"C") -> 9 | F27: =COUNTIF('🎯 RACI Matrix'!P8:P59,"I") -> 0 | G27: =C27+D27+E27+F27 -> 9 | H27: =IF(E27>8,"⚠ Over-consulted",IF(C27+D27=0,"⚠ No R/A","✅ OK")) -> ⚠ Over-consulted
B28: User Rep | C28: =COUNTIF('🎯 RACI Matrix'!Q8:Q59,"R") -> 0 | D28: =COUNTIF('🎯 RACI Matrix'!Q8:Q59,"A") -> 1 | E28: =COUNTIF('🎯 RACI Matrix'!Q8:Q59,"C") -> 9 | F28: =COUNTIF('🎯 RACI Matrix'!Q8:Q59,"I") -> 1 | G28: =C28+D28+E28+F28 -> 11 | H28: =IF(E28>8,"⚠ Over-consulted",IF(C28+D28=0,"⚠ No R/A","✅ OK")) -> ⚠ Over-consulted
B29: Steering Comm | C29: =COUNTIF('🎯 RACI Matrix'!R8:R59,"R") -> 0 | D29: =COUNTIF('🎯 RACI Matrix'!R8:R59,"A") -> 0 | E29: =COUNTIF('🎯 RACI Matrix'!R8:R59,"C") -> 5 | F29: =COUNTIF('🎯 RACI Matrix'!R8:R59,"I") -> 39 | G29: =C29+D29+E29+F29 -> 44 | H29: =IF(E29>8,"⚠ Over-consulted",IF(C29+D29=0,"⚠ No R/A","✅ OK")) -> ⚠ No R/A
B31: 📋 PHASE GATE CHECKLIST — Sign before proceeding
B32: Phase Gate | C32: Criterion 1 | D32: Criterion 2 | E32: Criterion 3 | F32: Status | G32: Signed By | H32: Date
B33: Post-Initiation | C33: RACI signed by Sponsor | D33: Charter approved | E33: Stakeholder Register complete | F33: ⬜ Not Started
B34: Post-Planning | C34: Requirements baselined | D34: Architecture signed off | E34: Risk Register active | F34: ⬜ Not Started
B35: Post-Design | C35: Security review passed | D35: Data model approved | E35: Migration strategy agreed | F35: ⬜ Not Started
B36: Post-Build | C36: All unit tests passed | D36: Code reviewed & approved | E36: Environments ready | F36: ⬜ Not Started
B37: Post-Testing | C37: Zero Sev-1 defects | D37: UAT sign-off complete | E37: Pen test cleared | F37: ⬜ Not Started
B38: Pre-Go-Live | C38: Go/No-Go decision logged | D38: Rollback plan approved | E38: Hypercare team briefed | F38: ⬜ Not Started

Sheet 📝 Change Log
A1: 📝 RACI CHANGE LOG — Record every change. This is your audit trail and governance evidence.
A4: Log ID | B4: Date | C4: Version | D4: Changed By | E4: Task # / Section | F4: Stakeholder Affected | G4: Change Type | H4: Previous RACI Code | I4: New RACI Code | J4: Reason / Justification | K4: Approved By | L4: Impact Assessment
A5: CL-001 | B5: 2025-01-15 | C5: 1.0 | D5: [PM Name] | E5: 1.3 | F5: Finance Mgr | G5: Role Added | H5: — | I5: A | J5: Finance Director added as Accountable for Data Migration after real-world failure pattern identified | K5: [Sponsor Name] | L5: Data migration ownership now explicit. Finance Director briefed.
A6: CL-002 | B6: 2025-01-20 | C6: 1.0 | D6: [PM Name] | E6: 5.5 | F6: User Rep | G6: Code Changed | H6: I | I6: A | J6: User Representative elevated from I to A on UAT execution — business must own sign-off, not observe it | K6: [Sponsor Name] | L6: UAT accountability strengthened. User Rep confirmed acceptance.
A7: CL-003 | B7: 2025-02-01 | C7: 1.0 | D7: [Sponsor Name] | E7: 7.1 | F7: Steering Comm | G7: Code Changed | H7: A | I7: C | J7: Steering Committee role changed from A to C on Go/No-Go. Sponsor retains A and sole authority | K7: [PM Name] | L7: Governance simplified. Steering informed post-decision.
A8: =IF(B8<>"","CL-"&TEXT(ROW()-4,"000"),"")
A9: =IF(B9<>"","CL-"&TEXT(ROW()-4,"000"),"")
A10: =IF(B10<>"","CL-"&TEXT(ROW()-4,"000"),"")
A11: =IF(B11<>"","CL-"&TEXT(ROW()-4,"000"),"")
A12: =IF(B12<>"","CL-"&TEXT(ROW()-4,"000"),"")
A13: =IF(B13<>"","CL-"&TEXT(ROW()-4,"000"),"")
A14: =IF(B14<>"","CL-"&TEXT(ROW()-4,"000"),"")
A15: =IF(B15<>"","CL-"&TEXT(ROW()-4,"000"),"")
A16: =IF(B16<>"","CL-"&TEXT(ROW()-4,"000"),"")
A17: =IF(B17<>"","CL-"&TEXT(ROW()-4,"000"),"")
A18: =IF(B18<>"","CL-"&TEXT(ROW()-4,"000"),"")
A19: =IF(B19<>"","CL-"&TEXT(ROW()-4,"000"),"")
... A79: =IF(B79<>"","CL-"&TEXT(ROW()-4,"000"),"")
